[2024-04-30T06:41:50.590+0000] {task_context_logger.py:104} ERROR - Executor reports task instance <TaskInstance: tweets_dag_v2.connect_to_database scheduled__2024-04-28T00:00:00+00:00 [queued]> finished (success) although the task says it's queued. (Info: None) Was the task killed externally?
