[2024-04-30T12:55:42.360+0000] {local_task_job_runner.py:120} INFO - ::group::Pre task execution logs
[2024-04-30T12:55:42.392+0000] {taskinstance.py:2073} INFO - Dependencies all met for dep_context=non-requeueable deps ti=<TaskInstance: tweets_dag_v4.connect_to_database manual__2024-04-30T08:44:45.732115+00:00 [queued]>
[2024-04-30T12:55:42.401+0000] {taskinstance.py:2073} INFO - Dependencies all met for dep_context=requeueable deps ti=<TaskInstance: tweets_dag_v4.connect_to_database manual__2024-04-30T08:44:45.732115+00:00 [queued]>
[2024-04-30T12:55:42.402+0000] {taskinstance.py:2303} INFO - Starting attempt 8 of 13
[2024-04-30T12:55:42.417+0000] {taskinstance.py:2327} INFO - Executing <Task(PythonOperator): connect_to_database> on 2024-04-30 08:44:45.732115+00:00
[2024-04-30T12:55:42.428+0000] {standard_task_runner.py:90} INFO - Running: ['***', 'tasks', 'run', 'tweets_dag_v4', 'connect_to_database', 'manual__2024-04-30T08:44:45.732115+00:00', '--job-id', '303', '--raw', '--subdir', 'DAGS_FOLDER/twitter_data_dag.py', '--cfg-path', '/tmp/tmpn99edn0n']
[2024-04-30T12:55:42.431+0000] {standard_task_runner.py:91} INFO - Job 303: Subtask connect_to_database
[2024-04-30T12:55:42.433+0000] {logging_mixin.py:188} WARNING - /home/***/.local/lib/python3.12/site-packages/***/task/task_runner/standard_task_runner.py:61 DeprecationWarning: This process (pid=489) is multi-threaded, use of fork() may lead to deadlocks in the child.
[2024-04-30T12:55:42.434+0000] {standard_task_runner.py:63} INFO - Started process 508 to run task
[2024-04-30T12:55:42.482+0000] {task_command.py:426} INFO - Running <TaskInstance: tweets_dag_v4.connect_to_database manual__2024-04-30T08:44:45.732115+00:00 [running]> on host 28012d5de722
[2024-04-30T12:55:42.575+0000] {taskinstance.py:2644} INFO - Exporting env vars: AIRFLOW_CTX_DAG_OWNER='stan' AIRFLOW_CTX_DAG_ID='tweets_dag_v4' AIRFLOW_CTX_TASK_ID='connect_to_database' AIRFLOW_CTX_EXECUTION_DATE='2024-04-30T08:44:45.732115+00:00' AIRFLOW_CTX_TRY_NUMBER='8' AIRFLOW_CTX_DAG_RUN_ID='manual__2024-04-30T08:44:45.732115+00:00'
[2024-04-30T12:55:42.578+0000] {taskinstance.py:430} INFO - ::endgroup::
[2024-04-30T12:55:42.651+0000] {taskinstance.py:441} INFO - ::group::Post task execution logs
[2024-04-30T12:55:42.652+0000] {taskinstance.py:2890} ERROR - Task failed with exception
Traceback (most recent call last):
  File "/home/airflow/.local/lib/python3.12/site-packages/airflow/models/taskinstance.py", line 465, in _execute_task
    result = _execute_callable(context=context, **execute_callable_kwargs)
             ^^^^^^^^^^^^^^^^^^^^^^^^^^^^^^^^^^^^^^^^^^^^^^^^^^^^^^^^^^^^^
  File "/home/airflow/.local/lib/python3.12/site-packages/airflow/models/taskinstance.py", line 432, in _execute_callable
    return execute_callable(context=context, **execute_callable_kwargs)
           ^^^^^^^^^^^^^^^^^^^^^^^^^^^^^^^^^^^^^^^^^^^^^^^^^^^^^^^^^^^^
  File "/home/airflow/.local/lib/python3.12/site-packages/airflow/models/baseoperator.py", line 400, in wrapper
    return func(self, *args, **kwargs)
           ^^^^^^^^^^^^^^^^^^^^^^^^^^^
  File "/home/airflow/.local/lib/python3.12/site-packages/airflow/operators/python.py", line 235, in execute
    return_value = self.execute_callable()
                   ^^^^^^^^^^^^^^^^^^^^^^^
  File "/home/airflow/.local/lib/python3.12/site-packages/airflow/operators/python.py", line 252, in execute_callable
    return self.python_callable(*self.op_args, **self.op_kwargs)
           ^^^^^^^^^^^^^^^^^^^^^^^^^^^^^^^^^^^^^^^^^^^^^^^^^^^^^
  File "/opt/airflow/dags/scripts/load_to_postgres.py", line 16, in load_csv_postgres
    df = pd.read_csv("/opt/airflow/dags/all_tweets.csv")
         ^^^^^^^^^^^^^^^^^^^^^^^^^^^^^^^^^^^^^^^^^^^^^^^
  File "/home/airflow/.local/lib/python3.12/site-packages/pandas/io/parsers/readers.py", line 948, in read_csv
    return _read(filepath_or_buffer, kwds)
           ^^^^^^^^^^^^^^^^^^^^^^^^^^^^^^^
  File "/home/airflow/.local/lib/python3.12/site-packages/pandas/io/parsers/readers.py", line 611, in _read
    parser = TextFileReader(filepath_or_buffer, **kwds)
             ^^^^^^^^^^^^^^^^^^^^^^^^^^^^^^^^^^^^^^^^^^
  File "/home/airflow/.local/lib/python3.12/site-packages/pandas/io/parsers/readers.py", line 1448, in __init__
    self._engine = self._make_engine(f, self.engine)
                   ^^^^^^^^^^^^^^^^^^^^^^^^^^^^^^^^^
  File "/home/airflow/.local/lib/python3.12/site-packages/pandas/io/parsers/readers.py", line 1705, in _make_engine
    self.handles = get_handle(
                   ^^^^^^^^^^^
  File "/home/airflow/.local/lib/python3.12/site-packages/pandas/io/common.py", line 863, in get_handle
    handle = open(
             ^^^^^
FileNotFoundError: [Errno 2] No such file or directory: '/opt/airflow/dags/all_tweets.csv'
[2024-04-30T12:55:42.670+0000] {taskinstance.py:1205} INFO - Marking task as UP_FOR_RETRY. dag_id=tweets_dag_v4, task_id=connect_to_database, execution_date=20240430T084445, start_date=20240430T125542, end_date=20240430T125542
[2024-04-30T12:55:42.682+0000] {standard_task_runner.py:110} ERROR - Failed to execute job 303 for task connect_to_database ([Errno 2] No such file or directory: '/opt/airflow/dags/all_tweets.csv'; 508)
[2024-04-30T12:55:42.729+0000] {local_task_job_runner.py:240} INFO - Task exited with return code 1
[2024-04-30T12:55:42.746+0000] {taskinstance.py:3482} INFO - 0 downstream tasks scheduled from follow-on schedule check
[2024-04-30T12:55:42.749+0000] {local_task_job_runner.py:222} INFO - ::endgroup::
