[2024-04-26T13:59:33.035+0000] {local_task_job_runner.py:120} INFO - ::group::Pre task execution logs
[2024-04-26T13:59:33.107+0000] {taskinstance.py:2073} INFO - Dependencies all met for dep_context=non-requeueable deps ti=<TaskInstance: dag_with_postgres.create_postgres_table scheduled__2024-03-12T00:00:00+00:00 [queued]>
[2024-04-26T13:59:33.125+0000] {taskinstance.py:2073} INFO - Dependencies all met for dep_context=requeueable deps ti=<TaskInstance: dag_with_postgres.create_postgres_table scheduled__2024-03-12T00:00:00+00:00 [queued]>
[2024-04-26T13:59:33.126+0000] {taskinstance.py:2303} INFO - Starting attempt 1 of 6
[2024-04-26T13:59:33.155+0000] {taskinstance.py:2327} INFO - Executing <Task(PostgresOperator): create_postgres_table> on 2024-03-12 00:00:00+00:00
[2024-04-26T13:59:33.170+0000] {standard_task_runner.py:90} INFO - Running: ['***', 'tasks', 'run', 'dag_with_postgres', 'create_postgres_table', 'scheduled__2024-03-12T00:00:00+00:00', '--job-id', '8', '--raw', '--subdir', 'DAGS_FOLDER/dag_with_postgres.py', '--cfg-path', '/tmp/tmpk_rwk3gv']
[2024-04-26T13:59:33.175+0000] {standard_task_runner.py:91} INFO - Job 8: Subtask create_postgres_table
[2024-04-26T13:59:33.182+0000] {logging_mixin.py:188} WARNING - /home/***/.local/lib/python3.12/site-packages/***/task/task_runner/standard_task_runner.py:61 DeprecationWarning: This process (pid=238) is multi-threaded, use of fork() may lead to deadlocks in the child.
[2024-04-26T13:59:33.183+0000] {standard_task_runner.py:63} INFO - Started process 245 to run task
[2024-04-26T13:59:33.259+0000] {task_command.py:426} INFO - Running <TaskInstance: dag_with_postgres.create_postgres_table scheduled__2024-03-12T00:00:00+00:00 [running]> on host 0ceb125076fc
[2024-04-26T13:59:33.419+0000] {taskinstance.py:2644} INFO - Exporting env vars: AIRFLOW_CTX_DAG_OWNER='stan' AIRFLOW_CTX_DAG_ID='dag_with_postgres' AIRFLOW_CTX_TASK_ID='create_postgres_table' AIRFLOW_CTX_EXECUTION_DATE='2024-03-12T00:00:00+00:00' AIRFLOW_CTX_TRY_NUMBER='1' AIRFLOW_CTX_DAG_RUN_ID='scheduled__2024-03-12T00:00:00+00:00'
[2024-04-26T13:59:33.420+0000] {taskinstance.py:430} INFO - ::endgroup::
[2024-04-26T13:59:33.451+0000] {sql.py:276} INFO - Executing: 
            CREATE TABLE if not exists dag_runs (
                dt date,
                dag_id character varying,
                primary key (dt, dag_id)
            )
        
        
[2024-04-26T13:59:33.467+0000] {base.py:84} INFO - Using connection ID 'postgres_localhost' for task execution.
[2024-04-26T13:59:33.480+0000] {base.py:84} INFO - Using connection ID 'postgres_localhost' for task execution.
[2024-04-26T13:59:33.487+0000] {taskinstance.py:441} INFO - ::group::Post task execution logs
[2024-04-26T13:59:33.488+0000] {taskinstance.py:2890} ERROR - Task failed with exception
Traceback (most recent call last):
  File "/home/airflow/.local/lib/python3.12/site-packages/airflow/models/taskinstance.py", line 465, in _execute_task
    result = _execute_callable(context=context, **execute_callable_kwargs)
             ^^^^^^^^^^^^^^^^^^^^^^^^^^^^^^^^^^^^^^^^^^^^^^^^^^^^^^^^^^^^^
  File "/home/airflow/.local/lib/python3.12/site-packages/airflow/models/taskinstance.py", line 432, in _execute_callable
    return execute_callable(context=context, **execute_callable_kwargs)
           ^^^^^^^^^^^^^^^^^^^^^^^^^^^^^^^^^^^^^^^^^^^^^^^^^^^^^^^^^^^^
  File "/home/airflow/.local/lib/python3.12/site-packages/airflow/models/baseoperator.py", line 400, in wrapper
    return func(self, *args, **kwargs)
           ^^^^^^^^^^^^^^^^^^^^^^^^^^^
  File "/home/airflow/.local/lib/python3.12/site-packages/airflow/providers/common/sql/operators/sql.py", line 282, in execute
    output = hook.run(
             ^^^^^^^^^
  File "/home/airflow/.local/lib/python3.12/site-packages/airflow/providers/common/sql/hooks/sql.py", line 397, in run
    with closing(self.get_conn()) as conn:
                 ^^^^^^^^^^^^^^^
  File "/home/airflow/.local/lib/python3.12/site-packages/airflow/providers/postgres/hooks/postgres.py", line 161, in get_conn
    self.conn = psycopg2.connect(**conn_args)
                ^^^^^^^^^^^^^^^^^^^^^^^^^^^^^
  File "/home/airflow/.local/lib/python3.12/site-packages/psycopg2/__init__.py", line 122, in connect
    conn = _connect(dsn, connection_factory=connection_factory, **kwasync)
           ^^^^^^^^^^^^^^^^^^^^^^^^^^^^^^^^^^^^^^^^^^^^^^^^^^^^^^^^^^^^^^^
psycopg2.OperationalError: could not translate host name "host.docker.local" to address: Name or service not known

[2024-04-26T13:59:33.515+0000] {taskinstance.py:1205} INFO - Marking task as UP_FOR_RETRY. dag_id=dag_with_postgres, task_id=create_postgres_table, execution_date=20240312T000000, start_date=20240426T135933, end_date=20240426T135933
[2024-04-26T13:59:33.604+0000] {standard_task_runner.py:110} ERROR - Failed to execute job 8 for task create_postgres_table (could not translate host name "host.docker.local" to address: Name or service not known
; 245)
[2024-04-26T13:59:33.640+0000] {local_task_job_runner.py:240} INFO - Task exited with return code 1
[2024-04-26T13:59:33.678+0000] {taskinstance.py:3482} INFO - 0 downstream tasks scheduled from follow-on schedule check
[2024-04-26T13:59:33.681+0000] {local_task_job_runner.py:222} INFO - ::endgroup::
