[2024-04-26T14:31:24.736+0000] {local_task_job_runner.py:120} INFO - ::group::Pre task execution logs
[2024-04-26T14:31:24.798+0000] {taskinstance.py:2073} INFO - Dependencies all met for dep_context=non-requeueable deps ti=<TaskInstance: tweets_dag.tweets_localhost scheduled__2024-03-19T00:00:00+00:00 [queued]>
[2024-04-26T14:31:24.810+0000] {taskinstance.py:2073} INFO - Dependencies all met for dep_context=requeueable deps ti=<TaskInstance: tweets_dag.tweets_localhost scheduled__2024-03-19T00:00:00+00:00 [queued]>
[2024-04-26T14:31:24.811+0000] {taskinstance.py:2303} INFO - Starting attempt 1 of 6
[2024-04-26T14:31:24.841+0000] {taskinstance.py:2327} INFO - Executing <Task(PostgresOperator): tweets_localhost> on 2024-03-19 00:00:00+00:00
[2024-04-26T14:31:24.852+0000] {logging_mixin.py:188} WARNING - /home/***/.local/lib/python3.12/site-packages/***/task/task_runner/standard_task_runner.py:61 DeprecationWarning: This process (pid=2353) is multi-threaded, use of fork() may lead to deadlocks in the child.
[2024-04-26T14:31:24.851+0000] {standard_task_runner.py:90} INFO - Running: ['***', 'tasks', 'run', 'tweets_dag', 'tweets_localhost', 'scheduled__2024-03-19T00:00:00+00:00', '--job-id', '102', '--raw', '--subdir', 'DAGS_FOLDER/twitter_data_dag.py', '--cfg-path', '/tmp/tmp1ekx8yf0']
[2024-04-26T14:31:24.853+0000] {standard_task_runner.py:63} INFO - Started process 2357 to run task
[2024-04-26T14:31:24.854+0000] {standard_task_runner.py:91} INFO - Job 102: Subtask tweets_localhost
[2024-04-26T14:31:24.931+0000] {task_command.py:426} INFO - Running <TaskInstance: tweets_dag.tweets_localhost scheduled__2024-03-19T00:00:00+00:00 [running]> on host 0ceb125076fc
[2024-04-26T14:31:25.047+0000] {taskinstance.py:2644} INFO - Exporting env vars: AIRFLOW_CTX_DAG_OWNER='stan' AIRFLOW_CTX_DAG_ID='tweets_dag' AIRFLOW_CTX_TASK_ID='tweets_localhost' AIRFLOW_CTX_EXECUTION_DATE='2024-03-19T00:00:00+00:00' AIRFLOW_CTX_TRY_NUMBER='1' AIRFLOW_CTX_DAG_RUN_ID='scheduled__2024-03-19T00:00:00+00:00'
[2024-04-26T14:31:25.048+0000] {taskinstance.py:430} INFO - ::endgroup::
[2024-04-26T14:31:25.069+0000] {sql.py:276} INFO - Executing: CREATE TABLE positive_tweets (
    id SERIAL PRIMARY KEY,
    roberta_neg NUMERIC,
    roberta_neu NUMERIC,
    roberta_pos NUMERIC,
    author VARCHAR(50),
    content TEXT,
    date_time TIMESTAMP,
    number_of_likes INTEGER,
    number_of_shares INTEGER
);

CREATE TABLE negative_tweets (
    id SERIAL PRIMARY KEY,
    roberta_neg NUMERIC,
    roberta_neu NUMERIC,
    roberta_pos NUMERIC,
    author VARCHAR(50),
    content TEXT,
    date_time TIMESTAMP,
    number_of_likes INTEGER,
    number_of_shares INTEGER
);

CREATE TABLE neutral_tweets (
    id SERIAL PRIMARY KEY,
    roberta_neg NUMERIC,
    roberta_neu NUMERIC,
    roberta_pos NUMERIC,
    author VARCHAR(50),
    content TEXT,
    date_time TIMESTAMP,
    number_of_likes INTEGER,
    number_of_shares INTEGER
);

[2024-04-26T14:31:25.081+0000] {base.py:84} INFO - Using connection ID 'postgres_localhost' for task execution.
[2024-04-26T14:31:25.092+0000] {base.py:84} INFO - Using connection ID 'postgres_localhost' for task execution.
[2024-04-26T14:31:25.106+0000] {taskinstance.py:441} INFO - ::group::Post task execution logs
[2024-04-26T14:31:25.107+0000] {taskinstance.py:2890} ERROR - Task failed with exception
Traceback (most recent call last):
  File "/home/airflow/.local/lib/python3.12/site-packages/airflow/models/taskinstance.py", line 465, in _execute_task
    result = _execute_callable(context=context, **execute_callable_kwargs)
             ^^^^^^^^^^^^^^^^^^^^^^^^^^^^^^^^^^^^^^^^^^^^^^^^^^^^^^^^^^^^^
  File "/home/airflow/.local/lib/python3.12/site-packages/airflow/models/taskinstance.py", line 432, in _execute_callable
    return execute_callable(context=context, **execute_callable_kwargs)
           ^^^^^^^^^^^^^^^^^^^^^^^^^^^^^^^^^^^^^^^^^^^^^^^^^^^^^^^^^^^^
  File "/home/airflow/.local/lib/python3.12/site-packages/airflow/models/baseoperator.py", line 400, in wrapper
    return func(self, *args, **kwargs)
           ^^^^^^^^^^^^^^^^^^^^^^^^^^^
  File "/home/airflow/.local/lib/python3.12/site-packages/airflow/providers/common/sql/operators/sql.py", line 282, in execute
    output = hook.run(
             ^^^^^^^^^
  File "/home/airflow/.local/lib/python3.12/site-packages/airflow/providers/common/sql/hooks/sql.py", line 397, in run
    with closing(self.get_conn()) as conn:
                 ^^^^^^^^^^^^^^^
  File "/home/airflow/.local/lib/python3.12/site-packages/airflow/providers/postgres/hooks/postgres.py", line 161, in get_conn
    self.conn = psycopg2.connect(**conn_args)
                ^^^^^^^^^^^^^^^^^^^^^^^^^^^^^
  File "/home/airflow/.local/lib/python3.12/site-packages/psycopg2/__init__.py", line 122, in connect
    conn = _connect(dsn, connection_factory=connection_factory, **kwasync)
           ^^^^^^^^^^^^^^^^^^^^^^^^^^^^^^^^^^^^^^^^^^^^^^^^^^^^^^^^^^^^^^^
psycopg2.OperationalError: connection to server at "host.docker.internal" (192.168.65.254), port 54321 failed: FATAL:  database "test" does not exist

[2024-04-26T14:31:25.125+0000] {taskinstance.py:1205} INFO - Marking task as UP_FOR_RETRY. dag_id=tweets_dag, task_id=tweets_localhost, execution_date=20240319T000000, start_date=20240426T143124, end_date=20240426T143125
[2024-04-26T14:31:25.210+0000] {standard_task_runner.py:110} ERROR - Failed to execute job 102 for task tweets_localhost (connection to server at "host.docker.internal" (192.168.65.254), port 54321 failed: FATAL:  database "test" does not exist
; 2357)
[2024-04-26T14:31:25.229+0000] {local_task_job_runner.py:240} INFO - Task exited with return code 1
[2024-04-26T14:31:25.254+0000] {taskinstance.py:3482} INFO - 0 downstream tasks scheduled from follow-on schedule check
[2024-04-26T14:31:25.256+0000] {local_task_job_runner.py:222} INFO - ::endgroup::
