[2024-04-26T14:02:09.096+0000] {local_task_job_runner.py:120} INFO - ::group::Pre task execution logs
[2024-04-26T14:02:09.263+0000] {taskinstance.py:2073} INFO - Dependencies all met for dep_context=non-requeueable deps ti=<TaskInstance: dag_with_postgres.create_postgres_table scheduled__2024-03-11T00:00:00+00:00 [queued]>
[2024-04-26T14:02:09.298+0000] {taskinstance.py:2073} INFO - Dependencies all met for dep_context=requeueable deps ti=<TaskInstance: dag_with_postgres.create_postgres_table scheduled__2024-03-11T00:00:00+00:00 [queued]>
[2024-04-26T14:02:09.306+0000] {taskinstance.py:2303} INFO - Starting attempt 2 of 7
[2024-04-26T14:02:09.394+0000] {taskinstance.py:2327} INFO - Executing <Task(PostgresOperator): create_postgres_table> on 2024-03-11 00:00:00+00:00
[2024-04-26T14:02:09.429+0000] {standard_task_runner.py:90} INFO - Running: ['***', 'tasks', 'run', 'dag_with_postgres', 'create_postgres_table', 'scheduled__2024-03-11T00:00:00+00:00', '--job-id', '24', '--raw', '--subdir', 'DAGS_FOLDER/dag_with_postgres.py', '--cfg-path', '/tmp/tmp8d6ejpl3']
[2024-04-26T14:02:09.439+0000] {standard_task_runner.py:91} INFO - Job 24: Subtask create_postgres_table
[2024-04-26T14:02:09.438+0000] {logging_mixin.py:188} WARNING - /home/***/.local/lib/python3.12/site-packages/***/task/task_runner/standard_task_runner.py:61 DeprecationWarning: This process (pid=456) is multi-threaded, use of fork() may lead to deadlocks in the child.
[2024-04-26T14:02:09.462+0000] {standard_task_runner.py:63} INFO - Started process 473 to run task
[2024-04-26T14:02:09.895+0000] {task_command.py:426} INFO - Running <TaskInstance: dag_with_postgres.create_postgres_table scheduled__2024-03-11T00:00:00+00:00 [running]> on host 0ceb125076fc
[2024-04-26T14:02:10.353+0000] {taskinstance.py:2644} INFO - Exporting env vars: AIRFLOW_CTX_DAG_OWNER='stan' AIRFLOW_CTX_DAG_ID='dag_with_postgres' AIRFLOW_CTX_TASK_ID='create_postgres_table' AIRFLOW_CTX_EXECUTION_DATE='2024-03-11T00:00:00+00:00' AIRFLOW_CTX_TRY_NUMBER='2' AIRFLOW_CTX_DAG_RUN_ID='scheduled__2024-03-11T00:00:00+00:00'
[2024-04-26T14:02:10.366+0000] {taskinstance.py:430} INFO - ::endgroup::
[2024-04-26T14:02:10.473+0000] {sql.py:276} INFO - Executing: 
            CREATE TABLE if not exists dag_runs (
                dt date,
                dag_id character varying,
                primary key (dt, dag_id)
            )
        
        
[2024-04-26T14:02:10.525+0000] {base.py:84} INFO - Using connection ID 'postgres_localhost' for task execution.
[2024-04-26T14:02:10.572+0000] {base.py:84} INFO - Using connection ID 'postgres_localhost' for task execution.
[2024-04-26T14:02:10.616+0000] {sql.py:457} INFO - Running statement: 
            CREATE TABLE if not exists dag_runs (
                dt date,
                dag_id character varying,
                primary key (dt, dag_id)
            )
        
        , parameters: None
[2024-04-26T14:02:10.655+0000] {taskinstance.py:441} INFO - ::group::Post task execution logs
[2024-04-26T14:02:10.658+0000] {taskinstance.py:2890} ERROR - Task failed with exception
Traceback (most recent call last):
  File "/home/airflow/.local/lib/python3.12/site-packages/airflow/models/taskinstance.py", line 465, in _execute_task
    result = _execute_callable(context=context, **execute_callable_kwargs)
             ^^^^^^^^^^^^^^^^^^^^^^^^^^^^^^^^^^^^^^^^^^^^^^^^^^^^^^^^^^^^^
  File "/home/airflow/.local/lib/python3.12/site-packages/airflow/models/taskinstance.py", line 432, in _execute_callable
    return execute_callable(context=context, **execute_callable_kwargs)
           ^^^^^^^^^^^^^^^^^^^^^^^^^^^^^^^^^^^^^^^^^^^^^^^^^^^^^^^^^^^^
  File "/home/airflow/.local/lib/python3.12/site-packages/airflow/models/baseoperator.py", line 400, in wrapper
    return func(self, *args, **kwargs)
           ^^^^^^^^^^^^^^^^^^^^^^^^^^^
  File "/home/airflow/.local/lib/python3.12/site-packages/airflow/providers/common/sql/operators/sql.py", line 282, in execute
    output = hook.run(
             ^^^^^^^^^
  File "/home/airflow/.local/lib/python3.12/site-packages/airflow/providers/common/sql/hooks/sql.py", line 404, in run
    self._run_command(cur, sql_statement, parameters)
  File "/home/airflow/.local/lib/python3.12/site-packages/airflow/providers/common/sql/hooks/sql.py", line 462, in _run_command
    cur.execute(sql_statement)
psycopg2.errors.UniqueViolation: duplicate key value violates unique constraint "pg_type_typname_nsp_index"
DETAIL:  Key (typname, typnamespace)=(dag_runs, 2200) already exists.

[2024-04-26T14:02:10.718+0000] {taskinstance.py:1205} INFO - Marking task as UP_FOR_RETRY. dag_id=dag_with_postgres, task_id=create_postgres_table, execution_date=20240311T000000, start_date=20240426T140209, end_date=20240426T140210
[2024-04-26T14:02:10.774+0000] {standard_task_runner.py:110} ERROR - Failed to execute job 24 for task create_postgres_table (duplicate key value violates unique constraint "pg_type_typname_nsp_index"
DETAIL:  Key (typname, typnamespace)=(dag_runs, 2200) already exists.
; 473)
[2024-04-26T14:02:10.839+0000] {local_task_job_runner.py:240} INFO - Task exited with return code 1
[2024-04-26T14:02:10.904+0000] {taskinstance.py:3482} INFO - 0 downstream tasks scheduled from follow-on schedule check
[2024-04-26T14:02:10.918+0000] {local_task_job_runner.py:222} INFO - ::endgroup::
