[2024-04-26T13:59:34.550+0000] {local_task_job_runner.py:120} INFO - ::group::Pre task execution logs
[2024-04-26T13:59:34.605+0000] {taskinstance.py:2073} INFO - Dependencies all met for dep_context=non-requeueable deps ti=<TaskInstance: dag_with_postgres.create_postgres_table scheduled__2024-03-21T00:00:00+00:00 [queued]>
[2024-04-26T13:59:34.617+0000] {taskinstance.py:2073} INFO - Dependencies all met for dep_context=requeueable deps ti=<TaskInstance: dag_with_postgres.create_postgres_table scheduled__2024-03-21T00:00:00+00:00 [queued]>
[2024-04-26T13:59:34.618+0000] {taskinstance.py:2303} INFO - Starting attempt 1 of 6
[2024-04-26T13:59:34.699+0000] {taskinstance.py:2327} INFO - Executing <Task(PostgresOperator): create_postgres_table> on 2024-03-21 00:00:00+00:00
[2024-04-26T13:59:34.706+0000] {standard_task_runner.py:90} INFO - Running: ['***', 'tasks', 'run', 'dag_with_postgres', 'create_postgres_table', 'scheduled__2024-03-21T00:00:00+00:00', '--job-id', '17', '--raw', '--subdir', 'DAGS_FOLDER/dag_with_postgres.py', '--cfg-path', '/tmp/tmpweegduom']
[2024-04-26T13:59:34.709+0000] {standard_task_runner.py:91} INFO - Job 17: Subtask create_postgres_table
[2024-04-26T13:59:34.713+0000] {logging_mixin.py:188} WARNING - /home/***/.local/lib/python3.12/site-packages/***/task/task_runner/standard_task_runner.py:61 DeprecationWarning: This process (pid=258) is multi-threaded, use of fork() may lead to deadlocks in the child.
[2024-04-26T13:59:34.715+0000] {standard_task_runner.py:63} INFO - Started process 261 to run task
[2024-04-26T13:59:34.775+0000] {task_command.py:426} INFO - Running <TaskInstance: dag_with_postgres.create_postgres_table scheduled__2024-03-21T00:00:00+00:00 [running]> on host 0ceb125076fc
[2024-04-26T13:59:34.866+0000] {taskinstance.py:2644} INFO - Exporting env vars: AIRFLOW_CTX_DAG_OWNER='stan' AIRFLOW_CTX_DAG_ID='dag_with_postgres' AIRFLOW_CTX_TASK_ID='create_postgres_table' AIRFLOW_CTX_EXECUTION_DATE='2024-03-21T00:00:00+00:00' AIRFLOW_CTX_TRY_NUMBER='1' AIRFLOW_CTX_DAG_RUN_ID='scheduled__2024-03-21T00:00:00+00:00'
[2024-04-26T13:59:34.867+0000] {taskinstance.py:430} INFO - ::endgroup::
[2024-04-26T13:59:34.890+0000] {sql.py:276} INFO - Executing: 
            CREATE TABLE if not exists dag_runs (
                dt date,
                dag_id character varying,
                primary key (dt, dag_id)
            )
        
        
[2024-04-26T13:59:34.902+0000] {base.py:84} INFO - Using connection ID 'postgres_localhost' for task execution.
[2024-04-26T13:59:34.913+0000] {base.py:84} INFO - Using connection ID 'postgres_localhost' for task execution.
[2024-04-26T13:59:34.917+0000] {taskinstance.py:441} INFO - ::group::Post task execution logs
[2024-04-26T13:59:34.918+0000] {taskinstance.py:2890} ERROR - Task failed with exception
Traceback (most recent call last):
  File "/home/airflow/.local/lib/python3.12/site-packages/airflow/models/taskinstance.py", line 465, in _execute_task
    result = _execute_callable(context=context, **execute_callable_kwargs)
             ^^^^^^^^^^^^^^^^^^^^^^^^^^^^^^^^^^^^^^^^^^^^^^^^^^^^^^^^^^^^^
  File "/home/airflow/.local/lib/python3.12/site-packages/airflow/models/taskinstance.py", line 432, in _execute_callable
    return execute_callable(context=context, **execute_callable_kwargs)
           ^^^^^^^^^^^^^^^^^^^^^^^^^^^^^^^^^^^^^^^^^^^^^^^^^^^^^^^^^^^^
  File "/home/airflow/.local/lib/python3.12/site-packages/airflow/models/baseoperator.py", line 400, in wrapper
    return func(self, *args, **kwargs)
           ^^^^^^^^^^^^^^^^^^^^^^^^^^^
  File "/home/airflow/.local/lib/python3.12/site-packages/airflow/providers/common/sql/operators/sql.py", line 282, in execute
    output = hook.run(
             ^^^^^^^^^
  File "/home/airflow/.local/lib/python3.12/site-packages/airflow/providers/common/sql/hooks/sql.py", line 397, in run
    with closing(self.get_conn()) as conn:
                 ^^^^^^^^^^^^^^^
  File "/home/airflow/.local/lib/python3.12/site-packages/airflow/providers/postgres/hooks/postgres.py", line 161, in get_conn
    self.conn = psycopg2.connect(**conn_args)
                ^^^^^^^^^^^^^^^^^^^^^^^^^^^^^
  File "/home/airflow/.local/lib/python3.12/site-packages/psycopg2/__init__.py", line 122, in connect
    conn = _connect(dsn, connection_factory=connection_factory, **kwasync)
           ^^^^^^^^^^^^^^^^^^^^^^^^^^^^^^^^^^^^^^^^^^^^^^^^^^^^^^^^^^^^^^^
psycopg2.OperationalError: could not translate host name "host.docker.local" to address: Name or service not known

[2024-04-26T13:59:34.934+0000] {taskinstance.py:1205} INFO - Marking task as UP_FOR_RETRY. dag_id=dag_with_postgres, task_id=create_postgres_table, execution_date=20240321T000000, start_date=20240426T135934, end_date=20240426T135934
[2024-04-26T13:59:35.020+0000] {standard_task_runner.py:110} ERROR - Failed to execute job 17 for task create_postgres_table (could not translate host name "host.docker.local" to address: Name or service not known
; 261)
[2024-04-26T13:59:35.050+0000] {local_task_job_runner.py:240} INFO - Task exited with return code 1
[2024-04-26T13:59:35.073+0000] {taskinstance.py:3482} INFO - 0 downstream tasks scheduled from follow-on schedule check
[2024-04-26T13:59:35.076+0000] {local_task_job_runner.py:222} INFO - ::endgroup::
